2025-04-19 13:13:09,337 - __main__ - ERROR - Unhandled exception: 
(<class 'click.exceptions.Exit'>, Exit(), <traceback object at 0x7f1483d81f80>)
Traceback (most recent call last):
  File "/home/dev/ThinkMark/docs_llm_scraper/utils.py", line 99, in load_config
    with open(config_path, 'r') as f:
         ^^^^^^^^^^^^^^^^^^^^^^
FileNotFoundError: [Errno 2] No such file or directory: 'config.json'

During handling of the above exception, another exception occurred:

Traceback (most recent call last):
  File "/home/dev/ThinkMark/docs_llm_scraper/cli.py", line 75, in main
    cfg = load_config(config)
          ^^^^^^^^^^^^^^^^^^^
  File "/home/dev/ThinkMark/docs_llm_scraper/utils.py", line 124, in load_config
    raise ValueError(f"Error loading config: {str(e)}")
ValueError: Error loading config: [Errno 2] No such file or directory: 'config.json'

During handling of the above exception, another exception occurred:

Traceback (most recent call last):
  File "/home/dev/ThinkMark/docs_llm_scraper/cli.py", line 83, in main
    raise typer.Exit(code=1)
click.exceptions.Exit
2025-04-19 13:25:08,741 - __main__ - ERROR - Unhandled exception: 
(<class 'click.exceptions.Exit'>, Exit(), <traceback object at 0x7f48f7e0dd80>)
Traceback (most recent call last):
  File "/home/dev/ThinkMark/docs_llm_scraper/cli.py", line 71, in main
    raise typer.Exit(code=1)
click.exceptions.Exit
